Workbook

Sheet Read me
A1: India ⇄ US cross-border moves — professional review pack
A2: Built from docs/CROSS_BORDER_MOVE_PLAN.md (commit 4032622). Law as understood on 2 Oct 2026 for US tax year 2026 and India FY 2026-27. Drafts for review, not advice.
A4: What this is | B4: WISING is building support for clients who move between India and the US: returning NRIs and people moving to the US. Before anything is built, every tax rule we plan to apply needs an Indian CA and a US CPA to confirm it, correct it, or say we're missing something.
A5: What we ask | B5: 1. Rules: give a verdict on each rule; if it's wrong, write the correct rule and the authority. 2. Open questions: answer the questions we couldn't settle ourselves. 3. Cases: tell us whether each case really behaves differently, and add any case we've missed. 4. Guide sample: tell us whether the step-by-step guidance is at the right level of detail.
A6: Who reviews what | B6: The 'Reviewer' column says who each row is for: India (CA), US (CPA), Treaty (both), or Both. Please answer only what's in your area; choose 'Not my area' otherwise.
A7: How to fill it in | B7: Only the yellow cells. Verdict, Keep-as-a-case and Right-level cells have drop-down lists. Sort by 'Priority' to see the rules tagged Verify first. References like 'plan §8.4' point to the full plan document, sent separately; you don't need it to answer.
A8: Section numbers | B8: Indian sections use ITA 1961 numbering (s.6, s.10(4)(ii), s.115H) unless a row says otherwise. Mapping them to the Income-tax Act 2025 is open question Q-1.
A10: Example of a completed row (format only — not a real answer)
A11: Ref | B11: Verdict | C11: Correct rule (if different) | D11: Authority / citation | E11: Comments
A12: G-13 | B12: Agree with change | C12: Also note: 1040-NR with wages subject to withholding is due 15 April. | D12: Instructions for Form 1040-NR (2026), 'When to file' | E12: Rest is correct.
A14: Progress
A15: Rules in this pack | B15: =COUNTA(Rules!A2:A173)
A16: Rules with a verdict | B16: =COUNTA(Rules!H2:H173)
A17: Agree | B17: =COUNTIF(Rules!H2:H173,"Agree")
A18: Agree with change | B18: =COUNTIF(Rules!H2:H173,"Agree with change")
A19: Disagree | B19: =COUNTIF(Rules!H2:H173,"Disagree")
A20: Not sure / needs research | B20: =COUNTIF(Rules!H2:H173,"Not sure / needs research")
A21: High-priority (Verify) rules | B21: =COUNTIF(Rules!G2:G173,"1 High")
A22: Open questions | B22: =COUNTA('Open questions'!A2:A26)
A23: Open questions answered | B23: =COUNTA('Open questions'!D2:D26)
A24: Cases | B24: =COUNTA(Cases!A2:A35)
A25: Cases reviewed | B25: =COUNTA(Cases!K2:K35)

Sheet Rules
A1: Ref | B1: Scenario | C1: Reviewer | D1: Topic | E1: Rule as drafted | F1: Our confidence | G1: Priority | H1: Verdict | I1: Correct rule (if different) | J1: Authority / citation | K1: Comments | L1: Reviewed by | M1: Date
A2: R-1 | B2: Both | C2: India (CA) | D2: No split year in India | E2: India's residential status (ROR / RNOR / NR) applies to the whole financial year (1 April – 31 March). A mid-year move does not split the Indian year. | F2: Certain | G2: =IF(ISNUMBER(SEARCH("Verify",F2)),"1 High",IF(ISNUMBER(SEARCH("Likely",F2)),"2 Medium","3 Low"))
A3: R-2 | B3: Moving to the US | C3: US (CPA) | D3: US residency start — substantial presence test | E3: Residency starts on the first day present in the US in the year the test is met, ignoring up to 10 days of earlier presence where the person had a closer connection to India. | F3: Certain | G3: =IF(ISNUMBER(SEARCH("Verify",F3)),"1 High",IF(ISNUMBER(SEARCH("Likely",F3)),"2 Medium","3 Low"))
A4: R-3 | B4: Moving to the US | C4: US (CPA) | D4: US residency start — green card | E4: Residency starts on the first day present in the US as a lawful permanent resident. | F4: Certain | G4: =IF(ISNUMBER(SEARCH("Verify",F4)),"1 High",IF(ISNUMBER(SEARCH("Likely",F4)),"2 Medium","3 Low"))
A5: R-4 | B5: Moving to the US | C5: US (CPA) | D5: First-year choice §7701(b)(4) | E5: Available when the substantial presence test isn't met in the arrival year but is met the next year: needs 31 consecutive days of presence and presence on 75% of the days from then to year-end. The return waits until next year's test is met (Form 4868 extension). | F5: Certain | G5: =IF(ISNUMBER(SEARCH("Verify",F5)),"1 High",IF(ISNUMBER(SEARCH("Likely",F5)),"2 Medium","3 Low"))
A6: R-5 | B6: Returning to India | C6: US (CPA) | D6: US residency end date | E6: Residency ends on the last day present if, for the rest of the year, the person has a tax home in India and a closer connection to India, and is not a US resident the next year. A statement is attached to the return; without that showing, the person is resident to 31 December. (Reg. 301.7701(b)-4) | F6: Likely (statement requirement to confirm) | G6: =IF(ISNUMBER(SEARCH("Verify",F6)),"1 High",IF(ISNUMBER(SEARCH("Likely",F6)),"2 Medium","3 Low"))
A7: R-6 | B7: Returning to India | C7: US (CPA) | D7: Green card end of residency | E7: US residency continues until the green card is surrendered (Form I-407) or abandonment is determined. | F7: Certain | G7: =IF(ISNUMBER(SEARCH("Verify",F7)),"1 High",IF(ISNUMBER(SEARCH("Likely",F7)),"2 Medium","3 Low"))
A8: R-7 | B8: Both | C8: US (CPA) | D8: US citizens | E8: US citizens never stop being US tax residents; a move changes FEIE and foreign-tax-credit planning, not the scope of US tax. | F8: Certain | G8: =IF(ISNUMBER(SEARCH("Verify",F8)),"1 High",IF(ISNUMBER(SEARCH("Likely",F8)),"2 Medium","3 Low"))
A9: R-8 | B9: Both | C9: India (CA) | D9: India residency tests (s.6) | E9: Resident if in India 182+ days in the FY, or 60+ days in the FY and 365+ days over the previous 4 FYs. The 60-day limb becomes 182 days for an Indian citizen leaving India for employment abroad (Explanation 1(a)) and for a citizen or person of Indian origin on a visit; for a visitor with Indian income over ₹15L it becomes 120 days. | F9: Certain | G9: =IF(ISNUMBER(SEARCH("Verify",F9)),"1 High",IF(ISNUMBER(SEARCH("Likely",F9)),"2 Medium","3 Low"))
A10: R-9 | B10: Returning to India | C10: India (CA) | D10: RNOR | E10: RNOR if non-resident in 9 of the previous 10 FYs, or in India 729 days or fewer over the previous 7 FYs. Also RNOR: deemed residents under s.6(1A) and visitors resident under the 120-day rule. | F10: Certain | G10: =IF(ISNUMBER(SEARCH("Verify",F10)),"1 High",IF(ISNUMBER(SEARCH("Likely",F10)),"2 Medium","3 Low"))
A11: R-10 | B11: Returning to India | C11: India (CA) | D11: Returning for good is not a visit | E11: A person returning to India permanently is not 'on a visit', so the plain 60-day limb (with 365 days over 4 years) applies. | F11: Likely (practitioner consensus) | G11: =IF(ISNUMBER(SEARCH("Verify",F11)),"1 High",IF(ISNUMBER(SEARCH("Likely",F11)),"2 Medium","3 Low"))
A12: R-11 | B12: Both | C12: US (CPA) | D12: Dual-status income attribution | E12: In a dual-status year each item is taxed under the rules of the period in which it was received or accrued (resident period: worldwide; non-resident period: US-source / effectively connected only), not by day-count. | F12: Likely (Reg. 1.871-13) | G12: =IF(ISNUMBER(SEARCH("Verify",F12)),"1 High",IF(ISNUMBER(SEARCH("Likely",F12)),"2 Medium","3 Low"))
A13: T-1 | B13: Both | C13: Treaty (CA + CPA) | D13: Art. 1(3) saving clause | E13: The US taxes its citizens and residents as if the treaty didn't exist, except for the articles listed (including 19, 21, 22, 25). Green-card holders are US residents for this purpose. | F13: Certain | G13: =IF(ISNUMBER(SEARCH("Verify",F13)),"1 High",IF(ISNUMBER(SEARCH("Likely",F13)),"2 Medium","3 Low"))
... A173: ST-6 | B173: Moving to the US | C173: US (CPA) | D173: State entry | E173: Part-year resident return for the arrival year. Most states give no credit for Indian tax. | F173: Likely | G173: =IF(ISNUMBER(SEARCH("Verify",F173)),"1 High",IF(ISNUMBER(SEARCH("Likely",F173)),"2 Medium","3 Low"))

Sheet Open questions
A1: Ref | B1: Question | C1: Reviewer | D1: Answer | E1: Authority / citation | F1: Comments | G1: Answered by | H1: Date
A2: Q-1 | B2: ITA 2025 section numbers for: s.6 residence (including 6(1A) and Explanation 1), s.10(4)(ii) NRE interest, s.10(15)(iv)(fa) FCNR/RFC interest, s.89A → s.158 and Form 40 (and the notified-country list), s.115H, s.10(10) / s.10(10AA), s.195, s.230. | C2: India (CA)
A3: Q-2 | B3: Reg. 301.7701(b)-4: the residency termination statement, and the last-year rules when the person returns in the following year. | C3: US (CPA)
A4: Q-3 | B4: Whether FBAR in a dual-status year covers the whole calendar year or the resident period only. | C4: US (CPA)
A5: Q-4 | B5: DTAA Art. 20 vs Art. 23 for lump-sum withdrawals, and §72(t) under the treaty: settled for full-year 1040-NR filers by an earlier CPA review. Still open: India's side of a lump sum (Art. 23(3) lets the source country tax, so India credits the US tax). | C5: Both
A6: Q-5 | B6: Which article governs US Social Security paid to an Indian resident, and the US withholding on it. | C6: Both
A7: Q-6 | B7: Art. 10/11 rate caps as amended; Art. 25(3) re-sourcing scope for capital gains on listed securities. | C7: Both
A8: Q-7 | B8: Reg. 1.871-13: pay for Indian work received after the US start date. | C8: US (CPA)
A9: Q-8 | B9: PFIC holding-period start for funds bought before becoming a US person; ULIP classification; Form 720 for Indian life-insurance premiums. | C9: Both
A10: Q-9 | B10: ADS recovery period for foreign residential rental property. | C10: US (CPA)
A11: Q-10 | B11: EPF classification for US purposes (employer contributions and growth). | C11: Both
A12: Q-11 | B12: Whether a person returning to India for good is 'on a visit' for the 182 / 120-day extension of the 60-day limb. Our reading: not on a visit, so the plain 60-day + 365-day test applies. | C12: Both
A13: Q-12 | B13: NRE deposits held to maturity after return (interest taxability from the return date); the FEMA penalty for not redesignating. | C13: India (CA)
... A26: Q-25 | B26: FEMA limits on NRI holdings in Indian partnership firms and proprietorships. | C26: India (CA)

Sheet Cases
A1: Case | B1: Direction | C1: US status | D1: Example move date | E1: India status (move FY) | F1: Household | G1: First or repeat move | H1: Key facts | I1: Why it is a separate case | J1: Plan persona | K1: Keep as a separate case? | L1: Expected outcome notes / missing variants | M1: Reviewed by
A2: C-A1 | B2: Returning to India | C2: Visa (H-1B) | D2: 15 Aug 2026 | E2: RNOR | F2: Single | G2: First | H2: 9 years in US; RSUs vesting after departure; 401(k) and Roth; keeps US rental condo; NRE/NRO accounts | I2: Core returnee case | J2: A1
A3: C-A2 | B3: Returning to India | C3: Green card, long-term resident (10 yrs) | D3: 15 Aug 2026 | E3: RNOR | F3: Single | G3: First | H3: Files I-407; net worth near §877A thresholds | I3: §877A covered-expatriate tests; Form 8854 | J3: A2
A4: C-A3 | B4: Returning to India | C4: Green card, under 8 years | D4: Jun 2026 | E4: RNOR | F4: Single | G4: First | H4: Files I-407 | I4: No §877A; residency ends at surrender
A5: C-A4 | B5: Returning to India | C5: Green card kept (re-entry permit) | D5: Jun 2026 | E5: RNOR | F5: Single | G5: First | H5: Lives in India, keeps card | I5: Stays US resident on worldwide income (G-3)
A6: C-A5 | B6: Returning to India | C6: US citizen (OCI) | D6: Aug 2026 | E6: RNOR | F6: Single | G6: First | H6: Relocating permanently; Indian employer | I6: US scope unchanged; FEIE vs FTC; EPF international worker | J6: A3
A7: C-A6 | B7: Returning to India | C7: Visa (H-1B) | D7: Aug 2026 | E7: ROR (no RNOR) | F7: Single | G7: First | H7: Only 3 years abroad | I7: Overlap Apr–Aug taxed by both; Art. 4/25 | J7: A4
A8: C-A7 | B8: Returning to India | C8: Visa (H-1B) | D8: Feb 2026 | E8: NR in FY 2025-26, RNOR from FY 2026-27 | F8: Single | G8: First | H8: Return in Jan–Mar | I8: Move year spans two Indian years
A9: C-A8 | B9: Returning to India | C9: Visa (H-1B) | D9: Nov 2026 | E9: NR for FY 2026-27 (unless 60+365), RNOR next FY | F9: Single | G9: First | H9: Late-year return; few prior visits | I9: India status for the move FY may be NR
A10: C-A9 | B10: Returning to India | C10: Visa (H-1B) | D10: Aug 2026 | E10: RNOR | F10: Single | G10: First | H10: Keeps US ties; no closer-connection claim | I10: US resident all year (residency end date not supported)
A11: C-A10 | B11: Returning to India | C11: Both spouses on visas | D11: Aug 2026 | E11: RNOR (both) | F11: Couple, same date | G11: First | H11: Filed MFJ in prior years | I11: No MFJ in dual-status year without election
A12: C-A11 | B12: Returning to India | C12: Both spouses on visas | D12: Spouse 1 Jun, spouse 2 Dec 2026 | E12: RNOR / NR | F12: Couple, different dates | G12: First | H12: One spouse stays to finish work | I12: Different residency periods per spouse
A13: C-A12 | B13: Returning to India | C13: US-citizen spouse + visa spouse | D13: Aug 2026 | E13: RNOR (visa spouse) | F13: Couple, same date | G13: First | H13: Citizen spouse stays a US taxpayer | I13: §6013(g) option for the non-citizen spouse
A14: C-A13 | B14: Returning to India | C14: Visa (H-1B) | D14: Aug 2026 | E14: RNOR | F14: Family with US-born children | G14: First | H14: Children are US citizens with Indian accounts | I14: Children's own US filings, FBAR, PFIC (G-4)
A15: C-A14 | B15: Returning to India | C15: F-1 student | D15: Jun 2026 | E15: RNOR | F15: Single | G15: First | H15: Exempt individual throughout | I15: US non-resident all along; no dual-status year
A16: C-A15 | B16: Returning to India | C16: Visa (H-1B) | D16: Aug 2026 | E16: ROR | F16: Single | G16: Repeat | H16: Returned to India once before within 4 years | I16: No RNOR on a repeat return (G-31)
A17: C-A16 | B17: Returning to India | C17: Visa / green card | D17: Aug 2026 | E17: RNOR | F17: Single | G17: First | H17: Consultant keeping US clients from India | I17: Business income sourcing; no US SE tax (G-11)
A18: C-A17 | B18: Returning to India | C18: Green card | D18: Aug 2026 | E18: RNOR | F18: Single | G18: First | H18: Owns an S-corp | I18: S election ends on becoming non-resident alien
A19: C-A18 | B19: Returning to India | C19: Green card / citizen, age 62+ | D19: Aug 2026 | E19: RNOR | F19: Couple, same date | G19: First | H19: Retiring: pension annuity, IRA, Social Security, RMDs soon | I19: Retirement-income treaty treatment; Medicare
A20: C-B1 | B20: Moving to the US | C20: Visa (H-1B) | D20: 15 Aug 2026 | E20: NR (left for employment) | F20: Single | G20: First | H20: Indian mutual funds; NRO FD | I20: SPT not met: full-year NRA vs first-year choice | J20: B1
A21: C-B2 | B21: Moving to the US | C21: Visa (H-1B) + H-4 spouse | D21: Feb 2026 (spouse Apr) | E21: ROR in FY 2025-26, NR after | F21: Couple, different dates | G21: First | H21: Spouse has Indian rental income | I21: Dual-status vs §6013(h); Jan–Mar move | J21: B2
A22: C-B3 | B22: Moving to the US | C22: F-1 student | D22: Aug 2026 | E22: NR | F22: Single | G22: First | H22: Funding from family in India | I22: Exempt individual; Art. 21; Form 8843 | J22: B3
A23: C-B4 | B23: Moving to the US | C23: Green card immigrant | D23: Nov 2026 | E23: ROR (182+ days in India) | F23: Couple, same date | G23: First | H23: Flat, EPF/PPF, ULIP | I23: India ROR in departure FY; overlap Nov–Mar | J23: B4
A24: C-B5 | B24: Moving to the US | C24: Visa (H-1B) | D24: May 2026 | E24: NR | F24: Single | G24: First | H24: SPT met in arrival year | I24: Dual-status from arrival date (most common arrival)
A25: C-B6 | B25: Moving to the US | C25: Green card immigrant | D25: Jun 2026 | E25: NR | F25: Single | G25: First | H25: Immigrant visa | I25: Residency from first day as permanent resident
A26: C-B7 | B26: Moving to the US | C26: J-1 researcher / teacher | D26: Aug 2026 | E26: NR | F26: Single | G26: First | H26: University appointment | I26: Art. 22 two-year exemption
A27: C-B8 | B27: Moving to the US | C27: L-1 transferee | D27: Jul 2026 | E27: NR | F27: Single | G27: First | H27: Paid partly by Indian employer (secondment) | I27: Indian payroll for a US resident; Art. 16
A28: C-B9 | B28: Moving to the US | C28: Visa (H-1B) | D28: Jul 2026 | E28: NR | F28: Single | G28: First | H28: Owns 20% of an Indian company and an LLP share | I28: Forms 5471/8865, CFC rules from arrival
A29: C-B10 | B29: Moving to the US | C29: Visa (H-1B) | D29: Jul 2026 | E29: NR | F29: Single | G29: First | H29: Member of an HUF | I29: Expected output: 'not covered' warning (G-5)
A30: C-B11 | B30: Moving to the US | C30: Both spouses on visas | D30: Jul 2026 | E30: NR (both) | F30: Couple, same date | G30: First | H30: Both employed in India before | I30: First-year choice + §6013(h) joint election
A31: C-B12 | B31: Moving to the US | C31: Visa (H-1B) | D31: Jul 2026 | E31: NR | F31: Couple, spouse stays in India | G31: First | H31: Spouse has Indian salary | I31: MFS vs §6013(g) for the non-resident spouse
A32: C-B13 | B32: Moving to the US | C32: Visa (H-1B) | D32: Mar 2026 | E32: NR | F32: Single | G32: Repeat | H32: Lived in the US 2 years ago | I32: SPT counts prior-year days; earlier PFIC history
A33: C-B14 | B33: Moving to the US | C33: US citizen raised in India | D33: Jul 2026 | E33: NR | F33: Single | G33: First | H33: Has always filed US returns from India | I33: US scope unchanged; India departure rules
A34: C-B15 | B34: Moving to the US | C34: Visa / green card | D34: Year after move | E34: RNOR risk in a later year | F34: Single | G34: First | H34: Visits India 130 days; Indian income over ₹15L | I34: Becoming resident in India again (G-2)
A35: C-B16 | B35: Moving to the US | C35: Visa (H-1B) | D35: Jul 2026 | E35: NR | F35: Single | G35: First | H35: Keeps working remotely for Indian employer for 2 months | I35: Indian pay received while US resident (G-38)
A37: Missing cases: add them in the rows below, starting with ID C-NEW1.
A38: C-NEW1
A39: C-NEW2
A40: C-NEW3
A41: C-NEW4
...

Sheet Guide sample
A1: Part | B1: Draft text (example finding: NRE account on return to India) | C1: Right level of detail? | D1: Correction / comments
A2: What changes | B2: The client becomes resident in India under FEMA on 15 Aug 2026. The Axis NRE account (₹19L) has to be converted.
A3: Why | B3: FEMA. The NRE interest exemption (s.10(4)(ii)) applies only to a person resident outside India under FEMA. [Likely; ITA 2025 section to map]
A4: What to do | B4: 1. Client, on return: tell the bank in writing; redesignate the NRE savings account as a resident account, or move the foreign-currency part to an RFC account. 2. Client: NRE deposits may run to maturity; interest from the return date is taxable. [Likely; check the bank's terms] 3. Specialist: include interest from the return date in Indian income. While RNOR, check FCNR/RFC money, whose interest stays exempt. 4. Specialist: if the client was a US resident for part of the year, report that period's interest on the US return.
A5: Forms and documents | B5: The bank's redesignation form; passport copy with the arrival stamp; the bank's interest certificate split at the return date.
A6: Deadline | B6: 15 Aug 2026 (the return date).
A7: Cost of not acting | B7: Indian tax plus interest on interest wrongly treated as exempt. The FEMA penalty needs legal confirmation.
A8: Doesn't apply if | B8: The client is back only on a visit and keeps FEMA non-resident status — specialist judgement.
A9: Confidence | B9: Likely

Sheet Context
A1: Decision windows used in the rules
A2: Direction | B2: Window | C2: US status | D2: India status | E2: Typical effect
A3: Returning to India | B3: W1 before leaving | C3: Resident | D3: NR | E3: US taxes; India doesn't.
B4: W2 RNOR years (move FY and up to about 2 more) | C4: Non-resident | D4: RNOR | E4: Often neither country taxes foreign-source gains. Exceptions: US real estate, and US-source income (US withholding still applies). India taxes it if it is first received in India (G-16).
B5: W3 after becoming ROR | C5: Non-resident | D5: ROR | E5: India taxes worldwide income, with credit for US tax.
A6: Moving to the US | B6: W1 before arriving | C6: Non-resident | D6: Resident | E6: India only. Best time to sell appreciated Indian assets.
B7: W2 after arriving | C7: Resident | D7: NR (or ROR in the departure FY) | E7: Both may tax. No US cost reset.
A9: Example timelines
A10: Example | B10: US tax year 2026 | C10: India FY 2025-26 (to 31 Mar 2026) | D10: India FY 2026-27 | E10: Months resident in both
A11: Returns to India 15 Aug 2026 (H-1B, 9 yrs in US) | B11: Resident 1 Jan–15 Aug; non-resident after | C11: NR | D11: RNOR for the whole year | E11: Apr–Aug 2026
A12: Arrives in US 10 Feb 2026 (H-1B) | B12: Non-resident to 9 Feb; resident from 10 Feb | C12: ROR for the whole year | D12: NR for the whole year | E12: 10 Feb–31 Mar 2026
A14: Confidence tags
A15: Certain | B15: Settled law, routinely applied.
A16: Likely | B16: Strong reading, widely applied, but with edge cases or fact-dependence.
A17: Verify | B17: Must be checked against the statute, treaty or ITA 2025 renumbering before we build it.
